Workbook

Sheet Read me
B2: QDE benchmark — measured results and statistical comparisons
B3: Quantum vs classical reservoir computing on chaotic time series · M.Sc. Data Engineering · Badrish Madapuji Srinivasan
B6: SHEETS
B7: DM comparisons | C7: All 321 per-seed Diebold-Mariano tests, with the 214-member pre-specified family flagged in the 'In 214 family' column.
B8: Why 214 and not 321 | C8: ESN(F) carries exactly the same feature budget as the quantum model at every size (64, 96, 128, 160, 192), so it IS feature-matched -- it sits outside the statistical family, not outside the matching. The family is the confirmatory test of the research question: ELM(F) asks whether the quantum feature map beats a classical one of the same size, and NG-RC asks whether it is competitive with the strongest classical method. ESN(F) answers neither; it is simply a weak reservoir on these tasks, four to five times worse than the quantum model. The quantum model wins all 107 of those comparisons, and that result is reported rather than buried -- it is the basis of the thesis's own point that beating a size-matched baseline is not a quantum advantage, since NG-RC remains several orders of magnitude ahead on 21 features.
B9: Measured results | C9: All 947 runs of the qubit-scaling study with every parameter that defines them: system, qubit count, feature budget F, seed, virtual nodes, window, shots and read-out set.
B10: Model scoreboard | C10: All 360 leaderboard runs across every model family on one common split, with all seven error metrics.
B11: Summary | C11: Counts and medians, computed from the other sheets by formula.
B13: COLOUR KEY
B14: Blue rows | C14: Quantum model (gate-based quantum reservoir, QRC).
B15: Grey rows | C15: Classical model (ELM, ESN, NG-RC, and the wider baseline field).
B16: Amber cell | C16: Best value in its category — lowest error. Driven by a formula, so it follows the data if a value changes.
B17: Coral row | C17: The single comparison of 214 that favoured the quantum model (Henon, 4 qubits, seed 0). See the note on that row.
B19: HOW TO READ NRMSE
B20: NRMSE | C20: Root-mean-square error divided by the standard deviation of the target. Lower is better. 1.0 is the score of predicting the mean, so any value near 1.0 means the model has learned essentially nothing.
B21: DM statistic | C21: Diebold-Mariano test of equal forecast accuracy. NEGATIVE means the quantum model had the smaller loss; POSITIVE means the classical model did.
B22: Holm-adjusted p | C22: Holm-Bonferroni step-down correction across the 214-member family, computed in Python because the step-down procedure has no clean spreadsheet form. All 214 remain significant after correction.
B24: PROVENANCE
B25: Source artifacts | C25: results/scaling_proof/{scores,dm}.csv and results/model_scoreboard_all_runs.csv, all committed. Built by scripts/build_results_workbook.py.
B26: Common conditions | C26: Every run: min-max scaling fitted on training data only, 60/20/20 chronological split, washout 100, horizon 1 step, ridge alpha 1e-6. Exact expectation values (no shot sampling) unless a shots column says otherwise.

Sheet DM comparisons
A1: System | B1: Qubits | C1: Quantum model | D1: Compared against | E1: In 214 family | F1: Seed | G1: DM statistic | H1: p-value | I1: Holm-adjusted p (family only) | J1: Winner | K1: Significant at 0.05 | L1: Note
A2: henon | B2: 4 | C2: QRC-rich | D2: ELM(F) — feature-matched control | E2: yes | F2: 0 | G2: -4.0866588 | H2: 5.6322271e-05 | I2: 9.7202313e-05 | J2: =IF(G2<0,"QUANTUM","Classical") -> QUANTUM | K2: =IF(H2<0.05,"yes","no") -> yes | L2: THE ONE REVERSAL OF 214. The control here is a random projection and this seed is its worst draw of twenty (0.0062 against a best of 0.0015); the quantum model scores 0.0044 on every seed. The Windows re-run reversed this same cell.
A3: henon | B3: 4 | C3: QRC-rich | D3: ELM(F) — feature-matched control | E3: yes | F3: 1 | G3: 9.6849259 | H3: 1.8298112e-19 | I3: 1.8847055e-17 | J3: =IF(G3<0,"QUANTUM","Classical") -> Classical | K3: =IF(H3<0.05,"yes","no") -> yes
A4: henon | B4: 4 | C4: QRC-rich | D4: ELM(F) — feature-matched control | E4: yes | F4: 2 | G4: 5.3265626 | H4: 1.9758736e-07 | I4: 2.766223e-06 | J4: =IF(G4<0,"QUANTUM","Classical") -> Classical | K4: =IF(H4<0.05,"yes","no") -> yes
A5: henon | B5: 4 | C5: QRC-rich | D5: ELM(F) — feature-matched control | E5: yes | F5: 3 | G5: 7.0597365 | H5: 1.1770674e-11 | I5: 4.4728561e-10 | J5: =IF(G5<0,"QUANTUM","Classical") -> Classical | K5: =IF(H5<0.05,"yes","no") -> yes
A6: henon | B6: 4 | C6: QRC-rich | D6: ELM(F) — feature-matched control | E6: yes | F6: 4 | G6: 11.596787 | H6: 6.5077533e-26 | I6: 1.0998103e-23 | J6: =IF(G6<0,"QUANTUM","Classical") -> Classical | K6: =IF(H6<0.05,"yes","no") -> yes
A7: henon | B7: 4 | C7: QRC-rich | D7: ELM(F) — feature-matched control | E7: yes | F7: 5 | G7: 10.319842 | H7: 1.5058901e-21 | I7: 2.0781283e-19 | J7: =IF(G7<0,"QUANTUM","Classical") -> Classical | K7: =IF(H7<0.05,"yes","no") -> yes
A8: henon | B8: 4 | C8: QRC-rich | D8: ELM(F) — feature-matched control | E8: yes | F8: 6 | G8: 8.6027352 | H8: 4.524371e-16 | I8: 2.9408412e-14 | J8: =IF(G8<0,"QUANTUM","Classical") -> Classical | K8: =IF(H8<0.05,"yes","no") -> yes
A9: henon | B9: 4 | C9: QRC-rich | D9: ELM(F) — feature-matched control | E9: yes | F9: 7 | G9: 9.9453399 | H9: 2.6006392e-20 | I9: 3.1467734e-18 | J9: =IF(G9<0,"QUANTUM","Classical") -> Classical | K9: =IF(H9<0.05,"yes","no") -> yes
A10: henon | B10: 4 | C10: QRC-rich | D10: ELM(F) — feature-matched control | E10: yes | F10: 8 | G10: 11.028336 | H10: 6.0522191e-24 | I10: 9.3204174e-22 | J10: =IF(G10<0,"QUANTUM","Classical") -> Classical | K10: =IF(H10<0.05,"yes","no") -> yes
A11: henon | B11: 4 | C11: QRC-rich | D11: ELM(F) — feature-matched control | E11: yes | F11: 9 | G11: 4.1226829 | H11: 4.8601156e-05 | I11: 9.7202313e-05 | J11: =IF(G11<0,"QUANTUM","Classical") -> Classical | K11: =IF(H11<0.05,"yes","no") -> yes
A12: henon | B12: 6 | C12: QRC-rich | D12: ELM(F) — feature-matched control | E12: yes | F12: 0 | G12: 12.369499 | H12: 1.206986e-28 | I12: 2.2329241e-26 | J12: =IF(G12<0,"QUANTUM","Classical") -> Classical | K12: =IF(H12<0.05,"yes","no") -> yes
A13: henon | B13: 6 | C13: QRC-rich | D13: ELM(F) — feature-matched control | E13: yes | F13: 1 | G13: 12.614085 | H13: 1.6045771e-29 | I13: 3.0486965e-27 | J13: =IF(G13<0,"QUANTUM","Classical") -> Classical | K13: =IF(H13<0.05,"yes","no") -> yes
A14: henon | B14: 6 | C14: QRC-rich | D14: ELM(F) — feature-matched control | E14: yes | F14: 2 | G14: 11.870285 | H14: 7.1349699e-27 | I14: 1.2414848e-24 | J14: =IF(G14<0,"QUANTUM","Classical") -> Classical | K14: =IF(H14<0.05,"yes","no") -> yes
... A215: mackeyglass | B215: 10 | C215: QRC-rich | D215: NG-RC — strong structural reference | E215: yes | F215: 4 | G215: 6.1737625 | H215: 9.7371139e-09 | I215: 1.7526805e-07 | J215: =IF(G215<0,"QUANTUM","Classical") -> Classical | K215: =IF(H215<0.05,"yes","no") -> yes
A216: henon | B216: 4 | C216: QRC-rich | D216: ESN(F) — size-matched reservoir | E216: no (extra) | F216: 0 | G216: -11.235314 | H216: 1.17382e-24 | J216: =IF(G216<0,"QUANTUM","Classical") -> QUANTUM | K216: =IF(H216<0.05,"yes","no") -> yes | L216: Quantum wins. ESN(F) is equally feature-matched but is the weakest model here, so this is expected and is reported, not hidden — it is the basis of the thesis's point that beating a size-matched baseline is not a quantum advantage. NG-RC beats both on 21 features.
A217: henon | B217: 4 | C217: QRC-rich | D217: ESN(F) — size-matched reservoir | E217: no (extra) | F217: 1 | G217: -13.773452 | H217: 9.7648135e-34 | J217: =IF(G217<0,"QUANTUM","Classical") -> QUANTUM | K217: =IF(H217<0.05,"yes","no") -> yes | L217: Quantum wins. ESN(F) is equally feature-matched but is the weakest model here, so this is expected and is reported, not hidden — it is the basis of the thesis's point that beating a size-matched baseline is not a quantum advantage. NG-RC beats both on 21 features.
A218: henon | B218: 4 | C218: QRC-rich | D218: ESN(F) — size-matched reservoir | E218: no (extra) | F218: 2 | G218: -11.511123 | H218: 1.2955992e-25 | J218: =IF(G218<0,"QUANTUM","Classical") -> QUANTUM | K218: =IF(H218<0.05,"yes","no") -> yes | L218: Quantum wins. ESN(F) is equally feature-matched but is the weakest model here, so this is expected and is reported, not hidden — it is the basis of the thesis's point that beating a size-matched baseline is not a quantum advantage. NG-RC beats both on 21 features.
A219: henon | B219: 4 | C219: QRC-rich | D219: ESN(F) — size-matched reservoir | E219: no (extra) | F219: 3 | G219: -11.899298 | H219: 5.6375494e-27 | J219: =IF(G219<0,"QUANTUM","Classical") -> QUANTUM | K219: =IF(H219<0.05,"yes","no") -> yes | L219: Quantum wins. ESN(F) is equally feature-matched but is the weakest model here, so this is expected and is reported, not hidden — it is the basis of the thesis's point that beating a size-matched baseline is not a quantum advantage. NG-RC beats both on 21 features.
A220: henon | B220: 4 | C220: QRC-rich | D220: ESN(F) — size-matched reservoir | E220: no (extra) | F220: 4 | G220: -11.606439 | H220: 6.0212378e-26 | J220: =IF(G220<0,"QUANTUM","Classical") -> QUANTUM | K220: =IF(H220<0.05,"yes","no") -> yes | L220: Quantum wins. ESN(F) is equally feature-matched but is the weakest model here, so this is expected and is reported, not hidden — it is the basis of the thesis's point that beating a size-matched baseline is not a quantum advantage. NG-RC beats both on 21 features.
A221: henon | B221: 4 | C221: QRC-rich | D221: ESN(F) — size-matched reservoir | E221: no (extra) | F221: 5 | G221: -8.8145181 | H221: 1.0207554e-16 | J221: =IF(G221<0,"QUANTUM","Classical") -> QUANTUM | K221: =IF(H221<0.05,"yes","no") -> yes | L221: Quantum wins. ESN(F) is equally feature-matched but is the weakest model here, so this is expected and is reported, not hidden — it is the basis of the thesis's point that beating a size-matched baseline is not a quantum advantage. NG-RC beats both on 21 features.
A222: henon | B222: 4 | C222: QRC-rich | D222: ESN(F) — size-matched reservoir | E222: no (extra) | F222: 6 | G222: -9.7370286 | H222: 1.2409819e-19 | J222: =IF(G222<0,"QUANTUM","Classical") -> QUANTUM | K222: =IF(H222<0.05,"yes","no") -> yes | L222: Quantum wins. ESN(F) is equally feature-matched but is the weakest model here, so this is expected and is reported, not hidden — it is the basis of the thesis's point that beating a size-matched baseline is not a quantum advantage. NG-RC beats both on 21 features.
A223: henon | B223: 4 | C223: QRC-rich | D223: ESN(F) — size-matched reservoir | E223: no (extra) | F223: 7 | G223: -10.117258 | H223: 7.0755228e-21 | J223: =IF(G223<0,"QUANTUM","Classical") -> QUANTUM | K223: =IF(H223<0.05,"yes","no") -> yes | L223: Quantum wins. ESN(F) is equally feature-matched but is the weakest model here, so this is expected and is reported, not hidden — it is the basis of the thesis's point that beating a size-matched baseline is not a quantum advantage. NG-RC beats both on 21 features.
A224: henon | B224: 4 | C224: QRC-rich | D224: ESN(F) — size-matched reservoir | E224: no (extra) | F224: 8 | G224: -10.936466 | H224: 1.2484638e-23 | J224: =IF(G224<0,"QUANTUM","Classical") -> QUANTUM | K224: =IF(H224<0.05,"yes","no") -> yes | L224: Quantum wins. ESN(F) is equally feature-matched but is the weakest model here, so this is expected and is reported, not hidden — it is the basis of the thesis's point that beating a size-matched baseline is not a quantum advantage. NG-RC beats both on 21 features.
A225: henon | B225: 4 | C225: QRC-rich | D225: ESN(F) — size-matched reservoir | E225: no (extra) | F225: 9 | G225: -11.455546 | H225: 2.0232171e-25 | J225: =IF(G225<0,"QUANTUM","Classical") -> QUANTUM | K225: =IF(H225<0.05,"yes","no") -> yes | L225: Quantum wins. ESN(F) is equally feature-matched but is the weakest model here, so this is expected and is reported, not hidden — it is the basis of the thesis's point that beating a size-matched baseline is not a quantum advantage. NG-RC beats both on 21 features.
A226: henon | B226: 6 | C226: QRC-rich | D226: ESN(F) — size-matched reservoir | E226: no (extra) | F226: 0 | G226: -9.5341834 | H226: 5.5942393e-19 | J226: =IF(G226<0,"QUANTUM","Classical") -> QUANTUM | K226: =IF(H226<0.05,"yes","no") -> yes | L226: Quantum wins. ESN(F) is equally feature-matched but is the weakest model here, so this is expected and is reported, not hidden — it is the basis of the thesis's point that beating a size-matched baseline is not a quantum advantage. NG-RC beats both on 21 features.
A227: henon | B227: 6 | C227: QRC-rich | D227: ESN(F) — size-matched reservoir | E227: no (extra) | F227: 1 | G227: -9.5951352 | H227: 3.5642117e-19 | J227: =IF(G227<0,"QUANTUM","Classical") -> QUANTUM | K227: =IF(H227<0.05,"yes","no") -> yes | L227: Quantum wins. ESN(F) is equally feature-matched but is the weakest model here, so this is expected and is reported, not hidden — it is the basis of the thesis's point that beating a size-matched baseline is not a quantum advantage. NG-RC beats both on 21 features.
... A322: mackeyglass | B322: 10 | C322: QRC-rich | D322: ESN(F) — size-matched reservoir | E322: no (extra) | F322: 4 | G322: -7.2629994 | H322: 4.4052643e-11 | J322: =IF(G322<0,"QUANTUM","Classical") -> QUANTUM | K322: =IF(H322<0.05,"yes","no") -> yes | L322: Quantum wins. ESN(F) is equally feature-matched but is the weakest model here, so this is expected and is reported, not hidden — it is the basis of the thesis's point that beating a size-matched baseline is not a quantum advantage. NG-RC beats both on 21 features.

Sheet Measured results
A1: System | B1: Qubit setting | C1: Model | D1: Model type | E1: Seed | F1: NRMSE | G1: Features F | H1: Points | I1: Virtual nodes V | J1: Window | K1: Shots | L1: Read-out | M1: NG-RC degree | N1: Best in this system+size
A2: henon | B2: 4 | C2: ELM(F) — feature-matched | D2: Classical | E2: 0 | F2: 0.006208618 | G2: 64 | H2: 1500 | J2: 5 | N2: =IF(F2=_xlfn.MINIFS($F$2:$F$948,$A$2:$A$948,$A2,$B$2:$B$948,$B2),"BEST","")
A3: henon | B3: 4 | C3: ELM(F) — feature-matched | D3: Classical | E3: 1 | F3: 0.0022297001 | G3: 64 | H3: 1500 | J3: 5 | N3: =IF(F3=_xlfn.MINIFS($F$2:$F$948,$A$2:$A$948,$A3,$B$2:$B$948,$B3),"BEST","")
A4: henon | B4: 4 | C4: ELM(F) — feature-matched | D4: Classical | E4: 2 | F4: 0.0031890061 | G4: 64 | H4: 1500 | J4: 5 | N4: =IF(F4=_xlfn.MINIFS($F$2:$F$948,$A$2:$A$948,$A4,$B$2:$B$948,$B4),"BEST","")
A5: henon | B5: 4 | C5: ELM(F) — feature-matched | D5: Classical | E5: 3 | F5: 0.0027323051 | G5: 64 | H5: 1500 | J5: 5 | N5: =IF(F5=_xlfn.MINIFS($F$2:$F$948,$A$2:$A$948,$A5,$B$2:$B$948,$B5),"BEST","")
A6: henon | B6: 4 | C6: ELM(F) — feature-matched | D6: Classical | E6: 4 | F6: 0.0014567989 | G6: 64 | H6: 1500 | J6: 5 | N6: =IF(F6=_xlfn.MINIFS($F$2:$F$948,$A$2:$A$948,$A6,$B$2:$B$948,$B6),"BEST","")
A7: henon | B7: 4 | C7: ELM(F) — feature-matched | D7: Classical | E7: 5 | F7: 0.0018990495 | G7: 64 | H7: 1500 | J7: 5 | N7: =IF(F7=_xlfn.MINIFS($F$2:$F$948,$A$2:$A$948,$A7,$B$2:$B$948,$B7),"BEST","")
A8: henon | B8: 4 | C8: ELM(F) — feature-matched | D8: Classical | E8: 6 | F8: 0.0023817089 | G8: 64 | H8: 1500 | J8: 5 | N8: =IF(F8=_xlfn.MINIFS($F$2:$F$948,$A$2:$A$948,$A8,$B$2:$B$948,$B8),"BEST","")
A9: henon | B9: 4 | C9: ELM(F) — feature-matched | D9: Classical | E9: 7 | F9: 0.0019382977 | G9: 64 | H9: 1500 | J9: 5 | N9: =IF(F9=_xlfn.MINIFS($F$2:$F$948,$A$2:$A$948,$A9,$B$2:$B$948,$B9),"BEST","")
A10: henon | B10: 4 | C10: ELM(F) — feature-matched | D10: Classical | E10: 8 | F10: 0.0015816057 | G10: 64 | H10: 1500 | J10: 5 | N10: =IF(F10=_xlfn.MINIFS($F$2:$F$948,$A$2:$A$948,$A10,$B$2:$B$948,$B10),"BEST","")
A11: henon | B11: 4 | C11: ELM(F) — feature-matched | D11: Classical | E11: 9 | F11: 0.0035050282 | G11: 64 | H11: 1500 | J11: 5 | N11: =IF(F11=_xlfn.MINIFS($F$2:$F$948,$A$2:$A$948,$A11,$B$2:$B$948,$B11),"BEST","")
A12: henon | B12: 4 | C12: ELM(F) — feature-matched | D12: Classical | E12: 10 | F12: 0.0018793452 | G12: 64 | H12: 1500 | J12: 5 | N12: =IF(F12=_xlfn.MINIFS($F$2:$F$948,$A$2:$A$948,$A12,$B$2:$B$948,$B12),"BEST","")
A13: henon | B13: 4 | C13: ELM(F) — feature-matched | D13: Classical | E13: 11 | F13: 0.0026989998 | G13: 64 | H13: 1500 | J13: 5 | N13: =IF(F13=_xlfn.MINIFS($F$2:$F$948,$A$2:$A$948,$A13,$B$2:$B$948,$B13),"BEST","")
... A41: henon | B41: 4 | C41: ESN(F) — size-matched | D41: Classical | E41: 19 | F41: 0.018867149 | G41: 64 | H41: 1500 | J41: 5 | N41: =IF(F41=_xlfn.MINIFS($F$2:$F$948,$A$2:$A$948,$A41,$B$2:$B$948,$B41),"BEST","")
A42: henon | B42: 4 | C42: NG-RC — strong reference | D42: Classical | E42: 0 | F42: 1.5867012e-06 | G42: 21 | H42: 1500 | J42: 5 | M42: 2 | N42: =IF(F42=_xlfn.MINIFS($F$2:$F$948,$A$2:$A$948,$A42,$B$2:$B$948,$B42),"BEST","") -> BEST
A43: henon | B43: 4 | C43: NG-RC — strong reference | D43: Classical | E43: 1 | F43: 1.5867012e-06 | G43: 21 | H43: 1500 | J43: 5 | M43: 2 | N43: =IF(F43=_xlfn.MINIFS($F$2:$F$948,$A$2:$A$948,$A43,$B$2:$B$948,$B43),"BEST","") -> BEST
A44: henon | B44: 4 | C44: NG-RC — strong reference | D44: Classical | E44: 2 | F44: 1.5867012e-06 | G44: 21 | H44: 1500 | J44: 5 | M44: 2 | N44: =IF(F44=_xlfn.MINIFS($F$2:$F$948,$A$2:$A$948,$A44,$B$2:$B$948,$B44),"BEST","") -> BEST
A45: henon | B45: 4 | C45: NG-RC — strong reference | D45: Classical | E45: 3 | F45: 1.5867012e-06 | G45: 21 | H45: 1500 | J45: 5 | M45: 2 | N45: =IF(F45=_xlfn.MINIFS($F$2:$F$948,$A$2:$A$948,$A45,$B$2:$B$948,$B45),"BEST","") -> BEST
A46: henon | B46: 4 | C46: NG-RC — strong reference | D46: Classical | E46: 4 | F46: 1.5867012e-06 | G46: 21 | H46: 1500 | J46: 5 | M46: 2 | N46: =IF(F46=_xlfn.MINIFS($F$2:$F$948,$A$2:$A$948,$A46,$B$2:$B$948,$B46),"BEST","") -> BEST
A47: henon | B47: 4 | C47: NG-RC — strong reference | D47: Classical | E47: 5 | F47: 1.5867012e-06 | G47: 21 | H47: 1500 | J47: 5 | M47: 2 | N47: =IF(F47=_xlfn.MINIFS($F$2:$F$948,$A$2:$A$948,$A47,$B$2:$B$948,$B47),"BEST","") -> BEST
A48: henon | B48: 4 | C48: NG-RC — strong reference | D48: Classical | E48: 6 | F48: 1.5867012e-06 | G48: 21 | H48: 1500 | J48: 5 | M48: 2 | N48: =IF(F48=_xlfn.MINIFS($F$2:$F$948,$A$2:$A$948,$A48,$B$2:$B$948,$B48),"BEST","") -> BEST
A49: henon | B49: 4 | C49: NG-RC — strong reference | D49: Classical | E49: 7 | F49: 1.5867012e-06 | G49: 21 | H49: 1500 | J49: 5 | M49: 2 | N49: =IF(F49=_xlfn.MINIFS($F$2:$F$948,$A$2:$A$948,$A49,$B$2:$B$948,$B49),"BEST","") -> BEST
A50: henon | B50: 4 | C50: NG-RC — strong reference | D50: Classical | E50: 8 | F50: 1.5867012e-06 | G50: 21 | H50: 1500 | J50: 5 | M50: 2 | N50: =IF(F50=_xlfn.MINIFS($F$2:$F$948,$A$2:$A$948,$A50,$B$2:$B$948,$B50),"BEST","") -> BEST
A51: henon | B51: 4 | C51: NG-RC — strong reference | D51: Classical | E51: 9 | F51: 1.5867012e-06 | G51: 21 | H51: 1500 | J51: 5 | M51: 2 | N51: =IF(F51=_xlfn.MINIFS($F$2:$F$948,$A$2:$A$948,$A51,$B$2:$B$948,$B51),"BEST","") -> BEST
A52: henon | B52: 4 | C52: NG-RC — strong reference | D52: Classical | E52: 10 | F52: 1.5867012e-06 | G52: 21 | H52: 1500 | J52: 5 | M52: 2 | N52: =IF(F52=_xlfn.MINIFS($F$2:$F$948,$A$2:$A$948,$A52,$B$2:$B$948,$B52),"BEST","") -> BEST
A53: henon | B53: 4 | C53: NG-RC — strong reference | D53: Classical | E53: 11 | F53: 1.5867012e-06 | G53: 21 | H53: 1500 | J53: 5 | M53: 2 | N53: =IF(F53=_xlfn.MINIFS($F$2:$F$948,$A$2:$A$948,$A53,$B$2:$B$948,$B53),"BEST","") -> BEST
... A61: henon | B61: 4 | C61: NG-RC — strong reference | D61: Classical | E61: 19 | F61: 1.5867012e-06 | G61: 21 | H61: 1500 | J61: 5 | M61: 2 | N61: =IF(F61=_xlfn.MINIFS($F$2:$F$948,$A$2:$A$948,$A61,$B$2:$B$948,$B61),"BEST","") -> BEST
A62: henon | B62: 4 | C62: QRC-rich (quantum) | D62: Quantum | E62: 0 | F62: 0.0043963941 | G62: 64 | H62: 1500 | I62: 4 | J62: 5 | K62: exact | L62: Z+X+Y+ZZ | N62: =IF(F62=_xlfn.MINIFS($F$2:$F$948,$A$2:$A$948,$A62,$B$2:$B$948,$B62),"BEST","")
A63: henon | B63: 4 | C63: QRC-rich (quantum) | D63: Quantum | E63: 1 | F63: 0.0044405797 | G63: 64 | H63: 1500 | I63: 4 | J63: 5 | K63: exact | L63: Z+X+Y+ZZ | N63: =IF(F63=_xlfn.MINIFS($F$2:$F$948,$A$2:$A$948,$A63,$B$2:$B$948,$B63),"BEST","")
A64: henon | B64: 4 | C64: QRC-rich (quantum) | D64: Quantum | E64: 2 | F64: 0.0044150281 | G64: 64 | H64: 1500 | I64: 4 | J64: 5 | K64: exact | L64: Z+X+Y+ZZ | N64: =IF(F64=_xlfn.MINIFS($F$2:$F$948,$A$2:$A$948,$A64,$B$2:$B$948,$B64),"BEST","")
A65: henon | B65: 4 | C65: QRC-rich (quantum) | D65: Quantum | E65: 3 | F65: 0.0044137061 | G65: 64 | H65: 1500 | I65: 4 | J65: 5 | K65: exact | L65: Z+X+Y+ZZ | N65: =IF(F65=_xlfn.MINIFS($F$2:$F$948,$A$2:$A$948,$A65,$B$2:$B$948,$B65),"BEST","")
A66: henon | B66: 4 | C66: QRC-rich (quantum) | D66: Quantum | E66: 4 | F66: 0.004432165 | G66: 64 | H66: 1500 | I66: 4 | J66: 5 | K66: exact | L66: Z+X+Y+ZZ | N66: =IF(F66=_xlfn.MINIFS($F$2:$F$948,$A$2:$A$948,$A66,$B$2:$B$948,$B66),"BEST","")
A67: henon | B67: 4 | C67: QRC-rich (quantum) | D67: Quantum | E67: 5 | F67: 0.0043776057 | G67: 64 | H67: 1500 | I67: 4 | J67: 5 | K67: exact | L67: Z+X+Y+ZZ | N67: =IF(F67=_xlfn.MINIFS($F$2:$F$948,$A$2:$A$948,$A67,$B$2:$B$948,$B67),"BEST","")
A68: henon | B68: 4 | C68: QRC-rich (quantum) | D68: Quantum | E68: 6 | F68: 0.0044714908 | G68: 64 | H68: 1500 | I68: 4 | J68: 5 | K68: exact | L68: Z+X+Y+ZZ | N68: =IF(F68=_xlfn.MINIFS($F$2:$F$948,$A$2:$A$948,$A68,$B$2:$B$948,$B68),"BEST","")
A69: henon | B69: 4 | C69: QRC-rich (quantum) | D69: Quantum | E69: 7 | F69: 0.0044079882 | G69: 64 | H69: 1500 | I69: 4 | J69: 5 | K69: exact | L69: Z+X+Y+ZZ | N69: =IF(F69=_xlfn.MINIFS($F$2:$F$948,$A$2:$A$948,$A69,$B$2:$B$948,$B69),"BEST","")
A70: henon | B70: 4 | C70: QRC-rich (quantum) | D70: Quantum | E70: 8 | F70: 0.0043722633 | G70: 64 | H70: 1500 | I70: 4 | J70: 5 | K70: exact | L70: Z+X+Y+ZZ | N70: =IF(F70=_xlfn.MINIFS($F$2:$F$948,$A$2:$A$948,$A70,$B$2:$B$948,$B70),"BEST","")
A71: henon | B71: 4 | C71: QRC-rich (quantum) | D71: Quantum | E71: 9 | F71: 0.0043932672 | G71: 64 | H71: 1500 | I71: 4 | J71: 5 | K71: exact | L71: Z+X+Y+ZZ | N71: =IF(F71=_xlfn.MINIFS($F$2:$F$948,$A$2:$A$948,$A71,$B$2:$B$948,$B71),"BEST","")
A72: henon | B72: 6 | C72: ELM(F) — feature-matched | D72: Classical | E72: 0 | F72: 0.0009013204 | G72: 96 | H72: 1500 | J72: 5 | N72: =IF(F72=_xlfn.MINIFS($F$2:$F$948,$A$2:$A$948,$A72,$B$2:$B$948,$B72),"BEST","")
A73: henon | B73: 6 | C73: ELM(F) — feature-matched | D73: Classical | E73: 1 | F73: 0.00099244956 | G73: 96 | H73: 1500 | J73: 5 | N73: =IF(F73=_xlfn.MINIFS($F$2:$F$948,$A$2:$A$948,$A73,$B$2:$B$948,$B73),"BEST","")
A74: henon | B74: 6 | C74: ELM(F) — feature-matched | D74: Classical | E74: 2 | F74: 0.0010620534 | G74: 96 | H74: 1500 | J74: 5 | N74: =IF(F74=_xlfn.MINIFS($F$2:$F$948,$A$2:$A$948,$A74,$B$2:$B$948,$B74),"BEST","")
...

Sheet Model scoreboard
A1: System | B1: Model | C1: Model type | D1: Family | E1: Approach | F1: Seed | G1: NRMSE | H1: RMSE | I1: MAE | J1: R2 | K1: sMAPE | L1: Max error | M1: Features | N1: Parameters | O1: Lookback | P1: Train rows | Q1: Test rows | R1: Best in system
A2: henon | B2: NG-RC | C2: Classical | D2: reservoir | E2: explicit delay + polynomial features + ridge | F2: 0 | G2: 6.8901409e-07 | H2: 1.9977414e-07 | I2: 1.5958222e-07 | J2: 1 | K2: 0.00021894667 | L2: 6.517863e-07 | M2: 10 | N2: 11 | O2: 3 | P2: 799 | Q2: 299 | R2: =IF(G2=_xlfn.MINIFS($G$2:$G$361,$A$2:$A$361,$A2),"BEST","") -> BEST
A3: henon | B3: NG-RC | C3: Classical | D3: reservoir | E3: explicit delay + polynomial features + ridge | F3: 1 | G3: 6.8901409e-07 | H3: 1.9977414e-07 | I3: 1.5958222e-07 | J3: 1 | K3: 0.00021894667 | L3: 6.517863e-07 | M3: 10 | N3: 11 | O3: 3 | P3: 799 | Q3: 299 | R3: =IF(G3=_xlfn.MINIFS($G$2:$G$361,$A$2:$A$361,$A3),"BEST","") -> BEST
A4: henon | B4: NG-RC | C4: Classical | D4: reservoir | E4: explicit delay + polynomial features + ridge | F4: 2 | G4: 6.8901409e-07 | H4: 1.9977414e-07 | I4: 1.5958222e-07 | J4: 1 | K4: 0.00021894667 | L4: 6.517863e-07 | M4: 10 | N4: 11 | O4: 3 | P4: 799 | Q4: 299 | R4: =IF(G4=_xlfn.MINIFS($G$2:$G$361,$A$2:$A$361,$A4),"BEST","") -> BEST
A5: henon | B5: NG-RC | C5: Classical | D5: reservoir | E5: explicit delay + polynomial features + ridge | F5: 3 | G5: 6.8901409e-07 | H5: 1.9977414e-07 | I5: 1.5958222e-07 | J5: 1 | K5: 0.00021894667 | L5: 6.517863e-07 | M5: 10 | N5: 11 | O5: 3 | P5: 799 | Q5: 299 | R5: =IF(G5=_xlfn.MINIFS($G$2:$G$361,$A$2:$A$361,$A5),"BEST","") -> BEST
A6: henon | B6: NG-RC | C6: Classical | D6: reservoir | E6: explicit delay + polynomial features + ridge | F6: 4 | G6: 6.8901409e-07 | H6: 1.9977414e-07 | I6: 1.5958222e-07 | J6: 1 | K6: 0.00021894667 | L6: 6.517863e-07 | M6: 10 | N6: 11 | O6: 3 | P6: 799 | Q6: 299 | R6: =IF(G6=_xlfn.MINIFS($G$2:$G$361,$A$2:$A$361,$A6),"BEST","") -> BEST
A7: henon | B7: ELM | C7: Classical | D7: reservoir | E7: random nonlinear projection + ridge | F7: 0 | G7: 0.0002078656 | H7: 6.0268973e-05 | I7: 4.6523601e-05 | J7: 0.99999996 | K7: 0.094409857 | L7: 0.00022211672 | M7: 300 | N7: 301 | O7: 3 | P7: 799 | Q7: 299 | R7: =IF(G7=_xlfn.MINIFS($G$2:$G$361,$A$2:$A$361,$A7),"BEST","")
A8: henon | B8: ELM | C8: Classical | D8: reservoir | E8: random nonlinear projection + ridge | F8: 4 | G8: 0.00021240948 | H8: 6.1586436e-05 | I8: 4.7370765e-05 | J8: 0.99999995 | K8: 0.1035417 | L8: 0.00023151961 | M8: 300 | N8: 301 | O8: 3 | P8: 799 | Q8: 299 | R8: =IF(G8=_xlfn.MINIFS($G$2:$G$361,$A$2:$A$361,$A8),"BEST","")
A9: henon | B9: ELM | C9: Classical | D9: reservoir | E9: random nonlinear projection + ridge | F9: 3 | G9: 0.00021620666 | H9: 6.2687399e-05 | I9: 4.7621601e-05 | J9: 0.99999995 | K9: 0.092507101 | L9: 0.00026760703 | M9: 300 | N9: 301 | O9: 3 | P9: 799 | Q9: 299 | R9: =IF(G9=_xlfn.MINIFS($G$2:$G$361,$A$2:$A$361,$A9),"BEST","")
A10: henon | B10: ELM | C10: Classical | D10: reservoir | E10: random nonlinear projection + ridge | F10: 2 | G10: 0.00023032357 | H10: 6.6780483e-05 | I10: 5.0272697e-05 | J10: 0.99999995 | K10: 0.10763164 | L10: 0.00030701352 | M10: 300 | N10: 301 | O10: 3 | P10: 799 | Q10: 299 | R10: =IF(G10=_xlfn.MINIFS($G$2:$G$361,$A$2:$A$361,$A10),"BEST","")
A11: henon | B11: ELM | C11: Classical | D11: reservoir | E11: random nonlinear projection + ridge | F11: 1 | G11: 0.00024470277 | H11: 7.0949619e-05 | I11: 5.5305516e-05 | J11: 0.99999994 | K11: 0.12019184 | L11: 0.00026028014 | M11: 300 | N11: 301 | O11: 3 | P11: 799 | Q11: 299 | R11: =IF(G11=_xlfn.MINIFS($G$2:$G$361,$A$2:$A$361,$A11),"BEST","")
A12: henon | B12: QRC-rich | C12: Quantum | D12: quantum | E12: gate-based quantum reservoir + ridge readout | F12: 3 | G12: 0.0043862171 | H12: 0.0012717487 | I12: 0.0010114813 | J12: 0.99998076 | K12: 1.4143647 | L12: 0.003765835 | M12: 96 | N12: 97 | O12: 5 | P12: 799 | Q12: 299 | R12: =IF(G12=_xlfn.MINIFS($G$2:$G$361,$A$2:$A$361,$A12),"BEST","")
A13: henon | B13: QRC-rich | C13: Quantum | D13: quantum | E13: gate-based quantum reservoir + ridge readout | F13: 4 | G13: 0.0043868438 | H13: 0.0012719304 | I13: 0.0010238238 | J13: 0.99998076 | K13: 1.3997185 | L13: 0.0037170537 | M13: 96 | N13: 97 | O13: 5 | P13: 799 | Q13: 299 | R13: =IF(G13=_xlfn.MINIFS($G$2:$G$361,$A$2:$A$361,$A13),"BEST","")
... A21: henon | B21: ESN | C21: Classical | D21: reservoir | E21: random recurrent reservoir + ridge readout | F21: 4 | G21: 0.0095003611 | H21: 0.002754554 | I21: 0.0021923183 | J21: 0.99990974 | K21: 2.0378236 | L21: 0.0086359708 | M21: 300 | N21: 301 | O21: 3 | P21: 799 | Q21: 299 | R21: =IF(G21=_xlfn.MINIFS($G$2:$G$361,$A$2:$A$361,$A21),"BEST","")
A22: henon | B22: RandomForest | C22: Classical | D22: ml | E22: tabular regressor on lag windows | F22: 4 | G22: 0.019292086 | H22: 0.0055935867 | I22: 0.003578888 | J22: 0.99962782 | K22: 2.0218409 | L22: 0.031535662 | M22: 4 | O22: 4 | P22: 799 | Q22: 299 | R22: =IF(G22=_xlfn.MINIFS($G$2:$G$361,$A$2:$A$361,$A22),"BEST","")
A23: henon | B23: RandomForest | C23: Classical | D23: ml | E23: tabular regressor on lag windows | F23: 1 | G23: 0.019478757 | H23: 0.0056477104 | I23: 0.0036188728 | J23: 0.99962058 | K23: 2.0148155 | L23: 0.03124346 | M23: 4 | O23: 4 | P23: 799 | Q23: 299 | R23: =IF(G23=_xlfn.MINIFS($G$2:$G$361,$A$2:$A$361,$A23),"BEST","")
A24: henon | B24: RandomForest | C24: Classical | D24: ml | E24: tabular regressor on lag windows | F24: 3 | G24: 0.019809436 | H24: 0.005743588 | I24: 0.0037717577 | J24: 0.99960759 | K24: 2.1266348 | L24: 0.030676548 | M24: 4 | O24: 4 | P24: 799 | Q24: 299 | R24: =IF(G24=_xlfn.MINIFS($G$2:$G$361,$A$2:$A$361,$A24),"BEST","")
A25: henon | B25: RandomForest | C25: Classical | D25: ml | E25: tabular regressor on lag windows | F25: 0 | G25: 0.019961413 | H25: 0.0057876527 | I25: 0.0037000325 | J25: 0.99960154 | K25: 2.0018167 | L25: 0.031784437 | M25: 4 | O25: 4 | P25: 799 | Q25: 299 | R25: =IF(G25=_xlfn.MINIFS($G$2:$G$361,$A$2:$A$361,$A25),"BEST","")
A26: henon | B26: RandomForest | C26: Classical | D26: ml | E26: tabular regressor on lag windows | F26: 2 | G26: 0.019993017 | H26: 0.0057968161 | I26: 0.0037407903 | J26: 0.99960028 | K26: 2.0444924 | L26: 0.03103782 | M26: 4 | O26: 4 | P26: 799 | Q26: 299 | R26: =IF(G26=_xlfn.MINIFS($G$2:$G$361,$A$2:$A$361,$A26),"BEST","")
A27: henon | B27: XGBoost | C27: Classical | D27: ml | E27: tabular regressor on lag windows | F27: 1 | G27: 0.026604235 | H27: 0.0077136858 | I27: 0.0047495871 | J27: 0.99929221 | K27: 2.1539352 | L27: 0.062974421 | M27: 4 | O27: 4 | P27: 799 | Q27: 299 | R27: =IF(G27=_xlfn.MINIFS($G$2:$G$361,$A$2:$A$361,$A27),"BEST","")
A28: henon | B28: XGBoost | C28: Classical | D28: ml | E28: tabular regressor on lag windows | F28: 3 | G28: 0.027473285 | H28: 0.0079656601 | I28: 0.0048384678 | J28: 0.99924522 | K28: 2.3339688 | L28: 0.068489698 | M28: 4 | O28: 4 | P28: 799 | Q28: 299 | R28: =IF(G28=_xlfn.MINIFS($G$2:$G$361,$A$2:$A$361,$A28),"BEST","")
A29: henon | B29: XGBoost | C29: Classical | D29: ml | E29: tabular regressor on lag windows | F29: 4 | G29: 0.027961489 | H29: 0.0081072108 | I29: 0.0051779572 | J29: 0.99921816 | K29: 2.4146976 | L29: 0.061647681 | M29: 4 | O29: 4 | P29: 799 | Q29: 299 | R29: =IF(G29=_xlfn.MINIFS($G$2:$G$361,$A$2:$A$361,$A29),"BEST","")
A30: henon | B30: XGBoost | C30: Classical | D30: ml | E30: tabular regressor on lag windows | F30: 2 | G30: 0.028120684 | H30: 0.0081533683 | I30: 0.0049844072 | J30: 0.99920923 | K30: 2.3191534 | L30: 0.071069208 | M30: 4 | O30: 4 | P30: 799 | Q30: 299 | R30: =IF(G30=_xlfn.MINIFS($G$2:$G$361,$A$2:$A$361,$A30),"BEST","")
A31: henon | B31: LightGBM | C31: Classical | D31: ml | E31: tabular regressor on lag windows | F31: 0 | G31: 0.02853082 | H31: 0.008272284 | I31: 0.0048666231 | J31: 0.99918599 | K31: 2.5144827 | L31: 0.054700501 | M31: 4 | O31: 4 | P31: 799 | Q31: 299 | R31: =IF(G31=_xlfn.MINIFS($G$2:$G$361,$A$2:$A$361,$A31),"BEST","")
A32: henon | B32: LightGBM | C32: Classical | D32: ml | E32: tabular regressor on lag windows | F32: 1 | G32: 0.02853082 | H32: 0.008272284 | I32: 0.0048666231 | J32: 0.99918599 | K32: 2.5144827 | L32: 0.054700501 | M32: 4 | O32: 4 | P32: 799 | Q32: 299 | R32: =IF(G32=_xlfn.MINIFS($G$2:$G$361,$A$2:$A$361,$A32),"BEST","")
A33: henon | B33: LightGBM | C33: Classical | D33: ml | E33: tabular regressor on lag windows | F33: 2 | G33: 0.02853082 | H33: 0.008272284 | I33: 0.0048666231 | J33: 0.99918599 | K33: 2.5144827 | L33: 0.054700501 | M33: 4 | O33: 4 | P33: 799 | Q33: 299 | R33: =IF(G33=_xlfn.MINIFS($G$2:$G$361,$A$2:$A$361,$A33),"BEST","")
... A46: henon | B46: kNN | C46: Classical | D46: ml | E46: tabular regressor on lag windows | F46: 4 | G46: 0.043082631 | H46: 0.012491466 | I46: 0.0085988161 | J46: 0.99814389 | K46: 2.8287302 | L46: 0.043505041 | M46: 4 | O46: 4 | P46: 799 | Q46: 299 | R46: =IF(G46=_xlfn.MINIFS($G$2:$G$361,$A$2:$A$361,$A46),"BEST","")
A47: henon | B47: ESN (reservoirpy) | C47: Classical | D47: reservoir | E47: library ESN cross-check | F47: 1 | G47: 0.044940447 | H47: 0.013030125 | I47: 0.010016932 | J47: 0.99798036 | K47: 6.7382672 | L47: 0.045665709 | M47: 300 | N47: 301 | O47: 3 | P47: 799 | Q47: 299 | R47: =IF(G47=_xlfn.MINIFS($G$2:$G$361,$A$2:$A$361,$A47),"BEST","")
A48: henon | B48: ESN (reservoirpy) | C48: Classical | D48: reservoir | E48: library ESN cross-check | F48: 3 | G48: 0.04496148 | H48: 0.013036223 | I48: 0.0099972562 | J48: 0.99797847 | K48: 6.4135754 | L48: 0.043586236 | M48: 300 | N48: 301 | O48: 3 | P48: 799 | Q48: 299 | R48: =IF(G48=_xlfn.MINIFS($G$2:$G$361,$A$2:$A$361,$A48),"BEST","")
A49: henon | B49: ESN (reservoirpy) | C49: Classical | D49: reservoir | E49: library ESN cross-check | F49: 0 | G49: 0.047878532 | H49: 0.013881999 | I49: 0.010581808 | J49: 0.99770765 | K49: 7.1009746 | L49: 0.0510165 | M49: 300 | N49: 301 | O49: 3 | P49: 799 | Q49: 299 | R49: =IF(G49=_xlfn.MINIFS($G$2:$G$361,$A$2:$A$361,$A49),"BEST","")
A50: henon | B50: ESN (reservoirpy) | C50: Classical | D50: reservoir | E50: library ESN cross-check | F50: 2 | G50: 0.049897958 | H50: 0.014467515 | I50: 0.010822088 | J50: 0.99751019 | K50: 7.1767631 | L50: 0.053023799 | M50: 300 | N50: 301 | O50: 3 | P50: 799 | Q50: 299 | R50: =IF(G50=_xlfn.MINIFS($G$2:$G$361,$A$2:$A$361,$A50),"BEST","")
A51: henon | B51: Transformer | C51: Classical | D51: dl | E51: torch sequence network on lag windows | F51: 4 | G51: 0.053815535 | H51: 0.015603385 | I51: 0.012193033 | J51: 0.99710389 | K51: 7.1788695 | L51: 0.045875644 | M51: 8 | N51: 8897 | O51: 8 | P51: 640 | Q51: 299 | R51: =IF(G51=_xlfn.MINIFS($G$2:$G$361,$A$2:$A$361,$A51),"BEST","")
A52: henon | B52: ESN (reservoirpy) | C52: Classical | D52: reservoir | E52: library ESN cross-check | F52: 4 | G52: 0.055445855 | H52: 0.016076084 | I52: 0.012053163 | J52: 0.99692576 | K52: 7.640888 | L52: 0.067402387 | M52: 300 | N52: 301 | O52: 3 | P52: 799 | Q52: 299 | R52: =IF(G52=_xlfn.MINIFS($G$2:$G$361,$A$2:$A$361,$A52),"BEST","")
A53: henon | B53: MLP | C53: Classical | D53: dl | E53: torch sequence network on lag windows | F53: 2 | G53: 0.057513735 | H53: 0.016675649 | I53: 0.012253188 | J53: 0.99669217 | K53: 6.4655282 | L53: 0.068155586 | M53: 8 | N53: 4801 | O53: 8 | P53: 640 | Q53: 299 | R53: =IF(G53=_xlfn.MINIFS($G$2:$G$361,$A$2:$A$361,$A53),"BEST","")
A54: henon | B54: Transformer | C54: Classical | D54: dl | E54: torch sequence network on lag windows | F54: 2 | G54: 0.062298562 | H54: 0.018062971 | I54: 0.01448979 | J54: 0.99611889 | K54: 8.1830419 | L54: 0.050825609 | M54: 8 | N54: 8897 | O54: 8 | P54: 640 | Q54: 299 | R54: =IF(G54=_xlfn.MINIFS($G$2:$G$361,$A$2:$A$361,$A54),"BEST","")
A55: henon | B55: Transformer | C55: Classical | D55: dl | E55: torch sequence network on lag windows | F55: 3 | G55: 0.064092847 | H55: 0.01858321 | I55: 0.015136525 | J55: 0.99589211 | K55: 7.7300142 | L55: 0.048557315 | M55: 8 | N55: 8897 | O55: 8 | P55: 640 | Q55: 299 | R55: =IF(G55=_xlfn.MINIFS($G$2:$G$361,$A$2:$A$361,$A55),"BEST","")
A56: henon | B56: Transformer | C56: Classical | D56: dl | E56: torch sequence network on lag windows | F56: 0 | G56: 0.06663786 | H56: 0.019321117 | I56: 0.014940731 | J56: 0.9955594 | K56: 8.2457343 | L56: 0.050260714 | M56: 8 | N56: 8897 | O56: 8 | P56: 640 | Q56: 299 | R56: =IF(G56=_xlfn.MINIFS($G$2:$G$361,$A$2:$A$361,$A56),"BEST","")
A57: henon | B57: MLP | C57: Classical | D57: dl | E57: torch sequence network on lag windows | F57: 4 | G57: 0.069841728 | H57: 0.020250052 | I57: 0.01510049 | J57: 0.99512213 | K57: 8.6339514 | L57: 0.068906783 | M57: 8 | N57: 4801 | O57: 8 | P57: 640 | Q57: 299 | R57: =IF(G57=_xlfn.MINIFS($G$2:$G$361,$A$2:$A$361,$A57),"BEST","")
A58: henon | B58: MLP | C58: Classical | D58: dl | E58: torch sequence network on lag windows | F58: 0 | G58: 0.089536024 | H58: 0.025960257 | I58: 0.019656279 | J58: 0.9919833 | K58: 7.396371 | L58: 0.078351709 | M58: 8 | N58: 4801 | O58: 8 | P58: 640 | Q58: 299 | R58: =IF(G58=_xlfn.MINIFS($G$2:$G$361,$A$2:$A$361,$A58),"BEST","")
... A65: henon | B65: QRC-v6 | C65: Quantum | D65: quantum | E65: gate-based quantum reservoir + ridge readout | F65: 4 | G65: 0.24431341 | H65: 0.070836727 | I65: 0.053661385 | J65: 0.94031096 | K65: 15.183399 | L65: 0.24732799 | M65: 24 | N65: 25 | O65: 5 | P65: 799 | Q65: 299 | R65: =IF(G65=_xlfn.MINIFS($G$2:$G$361,$A$2:$A$361,$A65),"BEST","")
...

Sheet Summary
B2: Summary — every figure below is a formula over the other sheets
B4: Pre-specified comparisons in the family | C4: =COUNTIF('DM comparisons'!E2:E322,"yes") -> 214 | D4: Quantum vs ELM(F) and quantum vs NG-RC, across systems, sizes and seeds.
B5: ... won by the classical model | C5: =COUNTIFS('DM comparisons'!E2:E322,"yes",'DM comparisons'!G2:G322,">0") -> 213 | D5: Positive DM statistic means the quantum model carried the larger loss.
B6: ... won by the quantum model | C6: =COUNTIFS('DM comparisons'!E2:E322,"yes",'DM comparisons'!G2:G322,"<0") -> 1 | D6: The single reversal, highlighted coral on the DM sheet.
B7: Largest raw p-value in the family | C7: =_xlfn.MAXIFS('DM comparisons'!H2:H322,'DM comparisons'!E2:E322,"yes") -> 5.6322271e-05 | D7: Every comparison in the family is significant; this is the weakest of them.
B8: Largest Holm-adjusted p-value in the family | C8: =MAX('DM comparisons'!I2:I322) -> 9.7202313e-05 | D8: All 214 survive correction for multiple testing.
B10: Mean NRMSE, quantum (scaling study) | C10: =AVERAGEIF('Measured results'!$D$2:$D$948,"Quantum",'Measured results'!$F$2:$F$948) -> 0.0077313243 | D10: Mean rather than median: a median over a filtered range needs an array formula, which does not survive being written by a script. The thesis reports medians; these are the means over the same rows.
B11: Mean NRMSE, classical (scaling study) | C11: =AVERAGEIF('Measured results'!$D$2:$D$948,"Classical",'Measured results'!$F$2:$F$948) -> 0.019523924 | D11: Same basis, classical rows only.
B12: Best quantum NRMSE / best classical NRMSE | C12: =_xlfn.MINIFS('Measured results'!$F$2:$F$948,'Measured results'!$D$2:$D$948,"Quantum")&" / "&_xlfn.MINIFS('Measured results'!$F$2:$F$948,'Measured results'!$D$2:$D$948,"Classical") -> 0.00372469754720013 / 0.0000015867011999559 | D12: The single best run of each type, anywhere in the scaling study.
B13: Best (lowest) NRMSE anywhere in the scaling study | C13: =MIN('Measured results'!F2:F948) -> 1.5867012e-06 | D13: Across all systems, sizes, models and seeds.
B14: Measured runs recorded | C14: =COUNTA('Measured results'!A2:A948) -> 947 | D14: One row per model, system, size and seed.
